Workbook

Sheet SUMMARY
B6: Amex Charge | D6: Business | E6: ='AMEX CHARGE'!F47 -> 3723.37 | F6: GST | G6: ='AMEX CHARGE'!F48 -> 338.48818 | I6: Personal Tax | J6: ='AMEX CHARGE'!F77 -> 1600.67 | M6: QUARTER GST POSITION DRAFT | P6: NET GST BANK ACCOUNT | R6: ='MAIN TXN ACC 000 0465 083 897'!H20 -> -499.60909
D7: Exempt | E7: ='AMEX CHARGE'!F77 -> 1600.67 | P7: EXPENSES | R7: =-G28 -> -397.04182
D8: CORP DONATIONS | E8: 0
P9: NET POSITION | R9: =SUM(R6:R8) -> -896.65091
B10: Amex Credit | D10: Business | E10: ='AMEX CREDIT'!H17 -> 463.79 | F10: GST | G10: ='AMEX CREDIT'!H18 -> 42.162727 | I10: Personal Tax | J10: ='AMEX CREDIT'!H37 -> 26
D11: Exempt | E11: ='AMEX CREDIT'!H29 -> 237.51
D12: CORP DONATIONS | E12: 0
B15: ANZ CARDS | D15: Business | E15: ='ANZ CARDS'!B5 -> 83.87 | F15: GST | G15: ='ANZ CARDS'!B6 -> 7.6245455 | I15: Personal Tax | J15: ='ANZ CARDS'!B14 -> 187.41
D16: Exempt | E16: ='ANZ CARDS'!B10 -> 83.87
B19: NAB CARDS | D19: Business | E19: =NAB!B4 -> 96.43 | F19: GST | G19: =NAB!B5 -> 8.7663636 | I19: Personal Tax | J19: =NAB!B19 -> 2961.64
D20: Exempt | E20: =NAB!B11 -> 30
B22: PayPal | D22: BUSINESS
D23: Exempt | E23: 0
B25: ANZ AFH | D25: BUSINESS | E25: ='ANZ - Advocating for Humanity'!B6 -> 0 | G25: ='ANZ - Advocating for Humanity'!B7 -> 0
D26: EXEMPT | E26: ='ANZ - Advocating for Humanity'!B12 -> 0
B28: Total | E28: =SUM(E6:E23) -> 6319.51 | F28: GST | G28: =SUM(G6:G19) -> 397.04182
B31: Claim
C34: Balance | E34: =SUM(E28:E33) -> 6319.51
D35: PLUS OWED FROM PRIOR EXPENSE CLAIM | E35: =F35 -> 316678.94 | F35: 316678.94 | I35: 316678.94
C36: DATE
C38: Balance | E38: =SUM(E34:E37) -> 322998.45
B40: 45546 | C40: 9000 | E40: =E38-C40 -> 313998.45
E41: =E40-C41 -> 313998.45
E42: =E41-C42 -> 313998.45
E43: =E42-C43 -> 313998.45
E44: =E43-C44 -> 313998.45
E45: =E44-C45 -> 313998.45
E46: =E45-C46 -> 313998.45
E47: =E46-C47 -> 313998.45
E48: =E47-C48 -> 313998.45

Sheet AMEX CHARGE
A1: Date | B1: Date Processed | C1: Description | D1: Card Member | E1: Account # | F1: Amount | G1: GST Status | H1: Category | I1: Foreign Spend Amount | J1: Commission | K1: Exchange Rate | L1: Additional Information | M1: Appears On Your Statement As | N1: Address | O1: Town/City | P1: Postcode | Q1: Country | R1: Reference
A2: 45536 | B2: 45536 | C2: WORKSPACE365.COM.AU SYDNEY | D2: JASON P MASTERS A/C | E2: -74020 | F2: 145.08 | G2: B | H2: OFFICE SUPPORT | L2: Arrive Date: 20240901 Depart Date: 20240901 Reference: 00 | M2: WORKSPACE365.COM.AU SYDNEY | N2: 62 66 GROSVENOR STREET | O2: SYDNEY NSW | P2: 2000 | Q2: AUSTRALIA | R2: 'AT242450003000010172750'
A3: 45538 | B3: 45539 | C3: AMAZON MARKETPLACE AU SYDNEY SOUTH | D3: JASON P MASTERS | E3: -76009 | F3: 137.76 | G3: B | H3: OFFICE EQUIPMENT | M3: AMAZON MARKETPLACE AU SYDNEY SOUTH | N3: 2 PARK STREET LEVEL 37 | O3: SYDNEY NSW | P3: 2000 | Q3: AUSTRALIA | R3: 'AT242480003000010181623'
A4: 45538 | B4: 45538 | C4: AMAZON MARKETPLACE AU SYDNEY SOUTH | D4: JASON P MASTERS | E4: -76009 | F4: 244.68 | G4: B | H4: OFFICE EQUIPMENT | M4: AMAZON MARKETPLACE AU SYDNEY SOUTH | N4: 2 PARK STREET LEVEL 37 | O4: SYDNEY NSW | P4: 2000 | Q4: AUSTRALIA | R4: 'AT242470003000010172989'
A5: 45538 | B5: 45539 | C5: NEWS PTY LIMITED SURRY SURRY HILLS | D5: JASON P MASTERS | E5: -76009 | F5: 30 | G5: B | H5: NEWSPAPERS & MAGAZINES | M5: NEWS PTY LIMITED SURRY SURRY HILLS | N5: 2 HOLT ST LEVEL 1 | O5: SURRY HILLS NSW | P5: 2010 | Q5: AUSTRALIA | R5: 'AT242480003000010211464'
A6: 45542 | B6: 45543 | C6: FAIRFAX - SUBSCRIPTION PYRMONT | D6: JASON P MASTERS A/C | E6: -74020 | F6: 64.99 | G6: B | H6: NEWSPAPERS & MAGAZINES | M6: FAIRFAX - SUBSCRIPTION PYRMONT | N6: LEVEL 5 1 DARLING ISLAND ROAD | O6: PYRMONT NSW | P6: 2009 | Q6: AUSTRALIA | R6: 'AT242520004000010211453'
A7: 45543 | B7: 45544 | C7: APPLE.COM/BILL SYDNEY | D7: JASON P MASTERS | E7: -76009 | F7: 19.99 | G7: B | H7: NEWSPAPERS & MAGAZINES | M7: APPLE.COM/BILL SYDNEY | N7: 255 PITT STREET CAPITAL CENTRE LEVEL 13 | O7: SYDNEY NSW | P7: 2000 | Q7: AUSTRALIA | R7: 'AT242530003000010158832'
A8: 45544 | B8: 45546 | C8: AMAZON MARKETPLACE AU SYDNEY SOUTH | D8: JASON P MASTERS A/C | E8: -74020 | F8: 100.81 | G8: B | H8: OFFICE EQUIPMENT | M8: AMAZON MARKETPLACE AU SYDNEY SOUTH | N8: 2 PARK STREET LEVEL 37 | O8: SYDNEY NSW | P8: 2000 | Q8: AUSTRALIA | R8: 'AT242550003000010174391'
A9: 45544 | B9: 45545 | C9: GLOBALX LEGAL SOLUTIONS BRISBANE | D9: MICHAELA WAKE | E9: -71034 | F9: 766.2 | G9: B | H9: LEGAL | L9: MERCHANDISE Reference: | M9: GLOBALX LEGAL SOLUTIONS BRISBANE | N9: LEVEL 6 WEST TOWER 410 ANN STREET | O9: BRISBANE QLD | P9: 4000 | Q9: AUSTRALIA | R9: 'AT242540004000010188523'
A10: 45545 | B10: 45547 | C10: GoDaddy Online Services Sydney | D10: JASON P MASTERS A/C | E10: -74020 | F10: 20.82 | G10: B | H10: INTERNET HOSTING | M10: GoDaddy Online Services Sydney | N10: WEWORK ATTN GODADDY LEVEL 4100 HARRIS STREET | O10: PYRMONT NSW | P10: 2009 | Q10: AUSTRALIA | R10: 'AT242560003000010205423'
A11: 45545 | B11: 45546 | C11: UNION UNIVERSITY & SCH SYDNEY | D11: JASON P MASTERS A/C | E11: -74020 | F11: 144.2 | G11: B | H11: PROF SUBSCRIPTION | M11: UNION UNIVERSITY & SCH SYDNEY | N11: 25 BENT ST | O11: SYDNEY NSW | P11: 2000 | Q11: AUSTRALIA | R11: 'AT242550003000010211743'
A12: 45546 | B12: 45546 | C12: AMAZON AU SYDNEY SOUTH | D12: JASON P MASTERS | E12: -76009 | F12: 216.94 | G12: B | H12: COMPUTER HARDWARE | M12: AMAZON AU SYDNEY SOUTH | N12: 2 PARK STREET LEVEL 37 | O12: SYDNEY NSW | P12: 2000 | Q12: AUSTRALIA | R12: 'AT242550003000010219121'
A13: 45546 | B13: 45547 | C13: AMAZON MARKETPLACE AU SYDNEY SOUTH | D13: JASON P MASTERS | E13: -76009 | F13: 29.99 | G13: B | H13: MOTOR VEHICLE EQUIPMENT | M13: AMAZON MARKETPLACE AU SYDNEY SOUTH | N13: 2 PARK STREET LEVEL 37 | O13: SYDNEY NSW | P13: 2000 | Q13: AUSTRALIA | R13: 'AT242560003000010187166'
A14: 45546 | B14: 45547 | C14: EXETEL PTY LTD NORTH SYDNEY | D14: JASON P MASTERS A/C | E14: -74020 | F14: 101 | G14: B | H14: INTERNET | M14: EXETEL PTY LTD NORTH SYDNEY | N14: LVL 5 121 WALKER ST | O14: NORTH SYDNEY NSW | P14: 2060 | Q14: AUSTRALIA | R14: 'AT242560003000010182289'
A15: 45548 | B15: 45548 | C15: EZI*IT SMART SOLUTIONS SYDNEY | D15: MICHAELA WAKE | E15: -71034 | F15: 148.5 | G15: B | H15: COMPUTER SERVICES | M15: EZI*IT SMART SOLUTIONS SYDNEY | N15: 20 40 MEAGHER STREET | O15: CHIPPENDALE NSW | P15: 2008 | Q15: AUSTRALIA | R15: 'AT242570009000010016983'
A16: 45549 | B16: 45551 | C16: TRANSPORT FOR NSW-OPAL CHIPPENDALE | D16: JASON P MASTERS A/C | E16: -74020 | F16: 20 | G16: B | H16: PUBLIC TRANSPORT | M16: TRANSPORT FOR NSW-OPAL CHIPPENDALE | N16: LEVEL 3 4 PARRAMATTA SQUARE 4PSQ 12 DARCY STREET | O16: PARRAMATTA NSW | P16: 2150 | Q16: AUSTRALIA | R16: 'AT242600003000010151961'
A17: 45550 | B17: 45550 | C17: FRAUDSEC T/A WHISPLI NORTH SYDNEY | D17: JASON P MASTERS A/C | E17: -74020 | F17: 108.9 | G17: B | H17: COMPUTER SOFTWARE | M17: FRAUDSEC T/A WHISPLI NORTH SYDNEY | N17: 24 32 LEXINGTON DRIVE SUITE A10 | O17: BELLA VISTA NSW | P17: 2153 | Q17: AUSTRALIA | R17: 'AT242590004000010171632'
A18: 45551 | B18: 45551 | C18: EZI*IT SMART SOLUTIONS SYDNEY | D18: MICHAELA WAKE | E18: -71034 | F18: 155.36 | G18: B | H18: COMPUTER SERVICES | M18: EZI*IT SMART SOLUTIONS SYDNEY | N18: 20 40 MEAGHER STREET | O18: CHIPPENDALE NSW | P18: 2008 | Q18: AUSTRALIA | R18: 'AT242600009000010056427'
A19: 45551 | B19: 45552 | C19: FONEBOX SYDNEY | D19: MICHAELA WAKE | E19: -71034 | F19: 16.5 | G19: B | H19: TELEPHONE | M19: FONEBOX SYDNEY | N19: LEVEL 4 580 GEORGE STREET | O19: SYDNEY NSW | P19: 2000 | Q19: AUSTRALIA | R19: 'AT242610004000010218604'
A20: 45552 | B20: 45553 | C20: APPLE.COM/BILL SYDNEY | D20: JASON P MASTERS | E20: -76009 | F20: =35.48-12.49 -> 22.99 | G20: B | H20: COMPUTER SOFTWARE | L20: 35.48 | M20: APPLE.COM/BILL SYDNEY | N20: 255 PITT STREET CAPITAL CENTRE LEVEL 13 | O20: SYDNEY NSW | P20: 2000 | Q20: AUSTRALIA | R20: 'AT242620004000010239541'
A21: 45552 | B21: 45554 | C21: SERVICE NSW BONDI JUNCTION | D21: JASON P MASTERS A/C | E21: -74020 | F21: 64.99 | G21: B | H21: TOLLS & PARKING | M21: SERVICE NSW BONDI JUNCTION | N21: 88 EBLEY ST | O21: BONDI JUNCTION NSW | P21: 2022 | Q21: AUSTRALIA | R21: 'AT242630003000010206993'
A22: 45554 | B22: 45555 | C22: AP NORTH RYDE LPO NORTH RYDE | D22: JASON P MASTERS A/C | E22: -74020 | F22: 113.38 | G22: B | H22: POSTAGE AND COURIERS | M22: AP NORTH RYDE LPO NORTH RYDE | N22: SHOP 15 203-213 COXS ROAD | O22: NORTH RYDE NSW | P22: 2113 | Q22: AUSTRALIA | R22: 'AT242640003000010226410'
A23: 45555 | B23: 45555 | C23: AMAZON MARKETPLACE AU SYDNEY SOUTH | D23: JASON P MASTERS | E23: -76009 | F23: 89.99 | G23: B | H23: MOTOR VEHICLE EQUIPMENT | M23: AMAZON MARKETPLACE AU SYDNEY SOUTH | N23: 2 PARK STREET LEVEL 37 | O23: SYDNEY NSW | P23: 2000 | Q23: AUSTRALIA | R23: 'AT242640009000010013276'
A24: 45555 | B24: 45555 | C24: AMAZON MARKETPLACE AU SYDNEY SOUTH | D24: JASON P MASTERS | E24: -76009 | F24: 209.99 | G24: B | H24: COMPUTER HARDWARE | M24: AMAZON MARKETPLACE AU SYDNEY SOUTH | N24: 2 PARK STREET LEVEL 37 | O24: SYDNEY NSW | P24: 2000 | Q24: AUSTRALIA | R24: 'AT242640009000010013275'
A25: 45555 | B25: 45556 | C25: APPLE.COM/BILL SYDNEY | D25: JASON P MASTERS | E25: -76009 | F25: 19.48 | G25: B | H25: NEWSPAPERS & MAGAZINES | M25: APPLE.COM/BILL SYDNEY | N25: 255 PITT STREET CAPITAL CENTRE LEVEL 13 | O25: SYDNEY NSW | P25: 2000 | Q25: AUSTRALIA | R25: 'AT242650003000010276299'
A26: 45556 | B26: 45557 | C26: APPLE.COM/BILL SYDNEY | D26: JASON P MASTERS | E26: -76009 | F26: 14.99 | G26: B | H26: STORAGE | M26: APPLE.COM/BILL SYDNEY | N26: 255 PITT STREET CAPITAL CENTRE LEVEL 13 | O26: SYDNEY NSW | P26: 2000 | Q26: AUSTRALIA | R26: 'AT242660004000010187814'
A27: 45556 | B27: 45558 | C27: APPLE.COM/BILL SYDNEY | D27: JASON P MASTERS | E27: -76009 | F27: 19 | G27: B | H27: COMPUTER SOFTWARE | M27: APPLE.COM/BILL SYDNEY | N27: 255 PITT STREET CAPITAL CENTRE LEVEL 13 | O27: SYDNEY NSW | P27: 2000 | Q27: AUSTRALIA | R27: 'AT242670003000010171824'
A28: 45556 | B28: 45557 | C28: APPLE.COM/BILL SYDNEY | D28: JASON P MASTERS | E28: -76009 | F28: 20.49 | G28: B | H28: INSURANCE | M28: APPLE.COM/BILL SYDNEY | N28: 255 PITT STREET CAPITAL CENTRE LEVEL 13 | O28: SYDNEY NSW | P28: 2000 | Q28: AUSTRALIA | R28: 'AT242660004000010230017'
A29: 45558 | B29: 45560 | C29: APPLE.COM/BILL SYDNEY | D29: JASON P MASTERS | E29: -76009 | F29: 4.49 | G29: B | H29: STORAGE | M29: APPLE.COM/BILL SYDNEY | N29: 255 PITT STREET CAPITAL CENTRE LEVEL 13 | O29: SYDNEY NSW | P29: 2000 | Q29: AUSTRALIA | R29: 'AT242690003000010238350'
A30: 45558 | B30: 45559 | C30: EXETEL PTY LTD NORTH SYDNEY | D30: JASON P MASTERS A/C | E30: -74020 | F30: -24.51 | G30: B | H30: INTERNET | M30: EXETEL PTY LTD NORTH SYDNEY | N30: LVL 5 121 WALKER ST | O30: NORTH SYDNEY NSW | P30: 2060 | Q30: AUSTRALIA | R30: 'AT242680003000010208634'
A31: 45559 | B31: 45560 | C31: APPLE.COM/BILL SYDNEY | D31: JASON P MASTERS A/C | E31: -74020 | F31: 1.49 | G31: B | H31: STORAGE | M31: APPLE.COM/BILL SYDNEY | N31: 255 PITT STREET CAPITAL CENTRE LEVEL 13 | O31: SYDNEY NSW | P31: 2000 | Q31: AUSTRALIA | R31: 'AT242690003000010239912'
A32: 45559 | B32: 45559 | C32: DESKY 0312 EAST BRISBANE | D32: JASON P MASTERS A/C | E32: -74020 | F32: 54.85 | G32: B | H32: OFFICE EQUIPMENT | M32: DESKY 0312 EAST BRISBANE | N32: 47 MANILLA STREET | O32: EAST BRISBANE QLD | P32: 4169 | Q32: AUSTRALIA | R32: 'AT242680003000010159920'
... A36: 45561 | B36: 45563 | C36: THE WILLIAM INGLIS OPI WARWICK FARM | D36: JASON P MASTERS A/C | E36: -74020 | F36: 81.45 | G36: B | H36: TRAVEL- DOM - ACCOMODATION | M36: THE WILLIAM INGLIS OPI WARWICK FARM | N36: 155 GOVERNOR MACQUARIE DRIVE | O36: WARWICK FARM NSW | P36: 2170 | Q36: AUSTRALIA | R36: 'AT242720003000010199341'
A37: 45562 | B37: 45563 | C37: AMPOL AUSTRALIA APP SYD SYDNEY | D37: JASON P MASTERS | E37: -76009 | F37: 91.49 | G37: B | H37: MOTOR VEHICLE PETROL | L37: OIL COMPANIES/NATL DEALER | M37: AMPOL AUSTRALIA APP SYD SYDNEY | N37: LEVEL 24 2 MARKET STREET | O37: SYDNEY NSW | P37: 2000 | Q37: AUSTRALIA | R37: 'AT242720003000010218410'
A38: 45562 | B38: 45563 | C38: AMPOL NORTH RYDE NORTH RYDE | D38: JASON P MASTERS | E38: -76009 | F38: 7.5 | G38: B | H38: MOTOR VEHICLE PETROL | L38: OIL COMPANIES/NATL DEALER | M38: AMPOL NORTH RYDE NORTH RYDE | N38: CNR WICKS EPPING ROAD | O38: NORTH RYDE NSW | P38: 2113 | Q38: AUSTRALIA | R38: 'AT242720003000010216674'
A39: 45562 | B39: 45563 | C39: KINDLE UNLTD 503-7150002 | D39: JASON P MASTERS A/C | E39: -74020 | F39: 13.99 | G39: B | H39: NEWSPAPERS & MAGAZINES | M39: KINDLE UNLTD 503-7150002 | N39: 410 TERRY AVE NORTH | O39: SEATTLE WA | P39: 98109 | Q39: UNITED STATES | R39: 'AT242720003000010230134'
A40: 45562 | B40: 45562 | C40: QUARTERLY ESSAY 1YR COLLINGWOOD | D40: JASON P MASTERS A/C | E40: -74020 | F40: 59.99 | G40: B | H40: NEWSPAPERS & MAGAZINES | M40: QUARTERLY ESSAY 1YR COLLINGWOOD | N40: 22-24 NORTHUMBERLAND ST | O40: COLLINGWOOD VIC | P40: 3066 | Q40: AUSTRALIA | R40: 'AT242710010000010017100'
A41: 45564 | B41: 45565 | C41: LS BELL'S MILK BAR BROKEN HILL | D41: JASON P MASTERS A/C | E41: -74020 | F41: 12.33 | G41: B | H41: TRAVEL-DOM-MEAL | M41: LS BELL'S MILK BAR BROKEN HILL | N41: 160 PATTON ST | O41: BROKEN HILL NSW | P41: 2880 | Q41: AUSTRALIA | R41: 'AT242740003000010147302'
A42: 45564 | B42: 45565 | C42: SYD301 SYD301 MASCOT | D42: JASON P MASTERS A/C | E42: -74020 | F42: 7.09 | G42: B | H42: TRAVEL-DOM-MEAL | M42: SYD301 SYD301 MASCOT | N42: SHOP 1 QANTAS TERMINAL SYDNEY DOMESTIC AIRPORT QANTAS DRIVE | O42: MASCOT NSW | P42: 2020 | Q42: AUSTRALIA | R42: 'AT242740010000010045726'
A43: 45564 | B43: 45564 | C43: TRANSPORT FOR NSW-OPAL CHIPPENDALE | D43: JASON P MASTERS A/C | E43: -74020 | F43: 20 | G43: B | H43: PUBLIC TRANSPORT | M43: TRANSPORT FOR NSW-OPAL CHIPPENDALE | N43: LEVEL 3 4 PARRAMATTA SQUARE 4PSQ 12 DARCY STREET | O43: PARRAMATTA NSW | P43: 2150 | Q43: AUSTRALIA | R43: 'AT242730010000010028221'
...

Sheet AMEX CREDIT
A1: Transaction Details | B1: American Express® Platinum Reserve Credit Card / Sep 01, 2023 to Sep 30, 2023
A2: Prepared for
A3: JASON P MASTERS
A4: Account Number
A5: XXXX-XXXXXX-25008
A7: Date | B7: Date Processed | C7: GST TYPE | D7: OUR DESCRIPTION | E7: Description | F7: Card Member | G7: Account # | H7: Amount | I7: Foreign Spend Amount | J7: Commission | K7: Exchange Rate | L7: Additional Information | M7: Appears On Your Statement As | N7: Address | O7: Town/City | P7: Postcode | Q7: Country | R7: Reference
A8: 45536 | B8: 45537 | C8: B | D8: MOBILE PHONES | E8: AMAYSIM MOBILE PTY LTD SYDNEY | F8: JASON P MASTERS | G8: -25008 | H8: 30 | M8: AMAYSIM MOBILE PTY LTD SYDNEY | N8: 6 17 19 BRIDGE STREET LEVEL | O8: SYDNEY NSW | P8: 2000 | Q8: AUSTRALIA | R8: 'AT242460004000010165778'
A9: 45537 | B9: 45538 | C9: B | D9: PROFESSIONAL ASSOCIATION | E9: THE ASSOCIATION OF PROF WEST MELBOURNE | F9: JOSHUA MASTERS | G9: -22021 | H9: 29.5 | M9: THE ASSOCIATION OF PROF WEST MELBOURNE | N9: 148 152 MILLER STREET | O9: WEST MELBOURNE VIC | P9: 3003 | Q9: AUSTRALIA | R9: 'AT242470004000010135399'
A10: 45540 | B10: 45541 | C10: B | D10: MOBILE PHONES | E10: TELSTRA BILL DIRECT DEB ADELAIDE | F10: JASON P MASTERS | G10: -25008 | H10: 174.34 | M10: TELSTRA BILL DIRECT DEB ADELAIDE | N10: GROUND FLOOR 30 PIRIE ST | O10: ADELAIDE SA | P10: 5000 | Q10: AUSTRALIA | R10: 'AT242500004000010143847'
A11: 45550 | B11: 45551 | C11: B | D11: NEWSPAPERS & MAGAZINES | E11: NEWS PTY LIMITED SURRY SURRY HILLS | F11: JASON P MASTERS | G11: -25008 | H11: 40 | M11: NEWS PTY LIMITED SURRY SURRY HILLS | N11: 2 HOLT ST LEVEL 1 | O11: SURRY HILLS NSW | P11: 2010 | Q11: AUSTRALIA | R11: 'AT242600004000010151522'
A12: 45552 | B12: 45553 | C12: B | D12: PUBLIC TRANSPORT | E12: TRANSPORT FOR NSW-OPAL CHIPPENDALE | F12: JOSHUA MASTERS | G12: -22021 | H12: 40 | M12: TRANSPORT FOR NSW-OPAL CHIPPENDALE | N12: LEVEL 3 4 PARRAMATTA SQUARE 4PSQ 12 DARCY STREET | O12: PARRAMATTA NSW | P12: 2150 | Q12: AUSTRALIA | R12: 'AT242620003000010147866'
A13: 45557 | B13: 45558 | C13: B | D13: COMPUTER SOFTWARE | E13: SQUIRREL STREET FRENCHS FOREST | F13: JASON P MASTERS | G13: -25008 | H13: 89.95 | M13: SQUIRREL STREET FRENCHS FOREST | N13: PO BOX 6488 | O13: FRENCHS FOREST NSW | P13: 2086 | Q13: AUSTRALIA | R13: 'AT242670004000010164889'
A14: 45558 | B14: 45559 | C14: B | D14: MOBILE PHONES | E14: AMAYSIM MOBILE PTY LTD SYDNEY | F14: JASON P MASTERS | G14: -25008 | H14: 30 | M14: AMAYSIM MOBILE PTY LTD SYDNEY | N14: 6 17 19 BRIDGE STREET LEVEL | O14: SYDNEY NSW | P14: 2000 | Q14: AUSTRALIA | R14: 'AT242680004000010138100'
A15: 45564 | B15: 45565 | C15: B | D15: MOBILE PHONES | E15: AMAYSIM MOBILE PTY LTD SYDNEY | F15: JASON P MASTERS | G15: -25008 | H15: 30 | M15: AMAYSIM MOBILE PTY LTD SYDNEY | N15: 6 17 19 BRIDGE STREET LEVEL | O15: SYDNEY NSW | P15: 2000 | Q15: AUSTRALIA | R15: 'AT242740004000010158621'
F17: subtotal | H17: =SUM(H8:H16) -> 463.79
F18: GST | H18: =H17/11 -> 42.162727
A22: 45542 | B22: 45543 | C22: E | D22: COMPUTER SOFTWARE | E22: LINKEDIN SYDNEY NSW | F22: JOSHUA MASTERS | G22: -22021 | H22: 39.99 | M22: LINKEDIN SYDNEY NSW | N22: CROFTS CHARTERED ACCOUNTS LEVEL 10 50 BERRY STREET | O22: NORTH SYDNEY NSW | P22: 2060 | Q22: AUSTRALIA | R22: 'AT242520003000010170897'
A23: 45548 | B23: 45550 | C23: E | D23: COMPUTER SOFTWARE | E23: ADOBE SYSTEMS Adobe Sys SAGGART | F23: JASON P MASTERS | G23: -25008 | H23: 79.99 | M23: ADOBE SYSTEMS Adobe Sys SAGGART | N23: 4-6 RIVERWALK CITY WEST BUSINESS CAMPUS SAGGART DUBLIN | P23: 24 | Q23: IRELAND | R23: 'AT242590003000010161255'
A24: 45548 | B24: 45548 | C24: E | D24: BANK FEES | E24: INTEREST CHARGES | F24: JASON P MASTERS | G24: -25008 | H24: 45.75 | M24: INTEREST CHARGES | R24: '10000000010913999992030'
A25: 45551 | B25: 45551 | C25: E | D25: COMPUTER SOFTWARE | E25: LINKEDIN PRE 9923808543 SINGAPORE | F25: JASON P MASTERS | G25: -25008 | H25: 33.79 | I25: 21.95 USD | J25: 0.98 | M25: LINKEDIN PRE 9923808543 SINGAPORE | N25: SUBMISSION USD SINGAPORE | P25: 0 | Q25: SINGAPORE | R25: 'AT242600010000010028061'
A26: 45561 | B26: 45562 | C26: E | D26: NEWSPAPERS & MAGAZINES | E26: D J*WSJ 800-568-7625 | F26: JASON P MASTERS | G26: -25008 | H26: 37.99 | I26: 25.29 USD | J26: 1.11 | M26: D J*WSJ 800-568-7625 | N26: 4300 RTE 1 NORTH | O26: SOUTH BRUNSWICK NJ | P26: 8852 | Q26: UNITED STATES | R26: 'AT242710009000010010786'
F29: SUBTOTAL | G29: =SUM(E8:E28) -> 0 | H29: =SUM(H22:H27) -> 237.51
A32: 45541 | B32: 45542 | C32: P | D32: MEDICAL-CPAP | E32: RESMED BELLA VISTA | F32: JASON P MASTERS | G32: -25008 | H32: 6.5 | M32: RESMED BELLA VISTA | N32: 1 ELIZABETH MACARTHUR DRIVE | O32: BELLA VISTA NSW | P32: 2153 | Q32: AUSTRALIA | R32: 'AT242510004000010157161'
A33: 45548 | B33: 45549 | C33: P | D33: MEDICAL-CPAP | E33: RESMED BELLA VISTA | F33: JASON P MASTERS | G33: -25008 | H33: 6.5 | M33: RESMED BELLA VISTA | N33: 1 ELIZABETH MACARTHUR DRIVE | O33: BELLA VISTA NSW | P33: 2153 | Q33: AUSTRALIA | R33: 'AT242580004000010164076'
A34: 45555 | B34: 45556 | C34: P | D34: MEDICAL-CPAP | E34: RESMED BELLA VISTA | F34: JASON P MASTERS | G34: -25008 | H34: 6.5 | M34: RESMED BELLA VISTA | N34: 1 ELIZABETH MACARTHUR DRIVE | O34: BELLA VISTA NSW | P34: 2153 | Q34: AUSTRALIA | R34: 'AT242650004000010182115'
A35: 45562 | B35: 45563 | C35: P | D35: MEDICAL-CPAP | E35: RESMED BELLA VISTA | F35: JASON P MASTERS | G35: -25008 | H35: 6.5 | M35: RESMED BELLA VISTA | N35: 1 ELIZABETH MACARTHUR DRIVE | O35: BELLA VISTA NSW | P35: 2153 | Q35: AUSTRALIA | R35: 'AT242720004000010164810'
F37: SUBTOTAL | H37: =SUM(H32:H36) -> 26
A39: 45536 | B39: 45537 | C39: Z | E39: CKO*PATREON* MEMBERSHIP DUBLIN | F39: JASON P MASTERS | G39: -25008 | H39: 42.5 | M39: CKO*PATREON* MEMBERSHIP DUBLIN | N39: SUITE 3 ONE EARLSFORT CENTRE DUBLIN | P39: DUBLIN 2 | Q39: IRELAND | R39: 'AT242460004000010165823'
A40: 45540 | B40: 45542 | C40: Z | E40: SENZA ESPRESSO BAR SYDNEY | F40: JASON P MASTERS | G40: -25008 | H40: 6 | M40: SENZA ESPRESSO BAR SYDNEY | N40: SHOP 1 LOBBY 255 GEORGE ST | O40: SYDNEY NSW | P40: 2000 | Q40: AUSTRALIA | R40: 'AT242510004000010157363'
A41: 45544 | B41: 45545 | C41: Z | D41: GAS | E41: RED ENERGY CREMORNE | F41: JASON P MASTERS | G41: -25008 | H41: 152.19 | M41: RED ENERGY CREMORNE | N41: 570 CHURCH ST | O41: CREMORNE VIC | P41: 3121 | Q41: AUSTRALIA | R41: 'AT242540003000010137082'
A42: 45546 | B42: 45547 | C42: Z | E42: CKO*PATREON* MEMBERSHIP DUBLIN | F42: JASON P MASTERS | G42: -25008 | H42: 17.6 | M42: CKO*PATREON* MEMBERSHIP DUBLIN | N42: SUITE 3 ONE EARLSFORT CENTRE DUBLIN | P42: DUBLIN 2 | Q42: IRELAND | R42: 'AT242560004000010143062'
A43: 45547 | B43: 45547 | C43: Z | E43: TEMU.COM PARRAMATTA | F43: JASON P MASTERS | G43: -25008 | H43: 104.78 | M43: TEMU.COM PARRAMATTA | N43: 60 2 2 OCONNELL STREET NSW | O43: PARRAMATTA NSW | P43: 2150 | Q43: AUSTRALIA | R43: 'AT242560009000010009777'
A44: 45549 | B44: 45551 | C44: Z | E44: KURTOSH CROWS NEST 6346 CROWS NEST | F44: JASON P MASTERS | G44: -25008 | H44: 45.52 | M44: KURTOSH CROWS NEST 6346 CROWS NEST | N44: 110-112 WILLOUGHBY ROAD | O44: CROWS NEST NSW | P44: 2065 | Q44: AUSTRALIA | R44: 'AT242600004000010151536'
A45: 45556 | B45: 45557 | C45: Z | E45: POCKETMAGS.COM REIGATE, SURREY | F45: JASON P MASTERS | G45: -25008 | H45: 23.97 | M45: POCKETMAGS.COM REIGATE, SURREY | N45: 31 LONDON ROAD JELLYFISH LTD | O45: "REIGATE, SURREY" ENG | P45: RH2 9SS | Q45: UNITED KINGDOM OF GB AND NI | R45: 'AT242660003000010179552'
A46: 45557 | B46: 45558 | C46: Z | E46: TEMU.COM*TEMU.COM PARRAMATTA | F46: JASON P MASTERS | G46: -25008 | H46: 3.68 | M46: TEMU.COM*TEMU.COM PARRAMATTA | N46: 60 2 2 OCONNELL STREET NSW | O46: PARRAMATTA NSW | P46: 2150 | Q46: AUSTRALIA | R46: 'AT242670004000010164922'
A47: 45557 | B47: 45558 | C47: Z | E47: TEMU.COM*TEMU.COM PARRAMATTA | F47: JASON P MASTERS | G47: -25008 | H47: 120.2 | M47: TEMU.COM*TEMU.COM PARRAMATTA | N47: 60 2 2 OCONNELL STREET NSW | O47: PARRAMATTA NSW | P47: 2150 | Q47: AUSTRALIA | R47: 'AT242670004000010164921'

Sheet ANZ CARDS
A1: Date | B1: Amount | C1: Bus/Exempt GST/Pers Tax/ZOther | D1: Category | E1: Amex Credit Card-Merchant | F1: Remarks | G1: JPM's Review | H1: JPM's Review
A2: 45543 | B2: 83.87 | C2: E | D2: BANK FEES | E2: INTEREST CHARGED ON PURCHASES
B5: =SUM(B2:B4) -> 83.87 | C5: SUBTOTAL
B6: =B5/11 -> 7.6245455 | C6: GST
A8: 45543 | B8: 83.87 | C8: E | D8: BANK FEES | E8: INTEREST CHARGED ON PURCHASES
B10: =SUM(B8:B9) -> 83.87 | C10: SUBTOTAL
A12: 45537 | B12: 187.41 | C12: P | D12: MEDICAL-DOCTOR | E12: Hunters Hill Medical Hunters Hill
B14: =SUM(B12) -> 187.41 | C14: SUBTOTAL
A18: 45537 | B18: 22.82 | C18: Z | E18: VSA_THELIVEN.COM TALLINN 14.99 USD 0.66 AUD
A19: 45537 | B19: 30.45 | C19: Z | E19: VSA_THELIVEN.COM TALLINN 19.99 USD 0.89 AUD
A20: 45539 | B20: 86.88 | C20: Z | E20: JIAHE TRADING AUSTRALI CHATSWOOD
A21: 45544 | B21: 78.01 | C21: Z | E21: eBay O*04-12048-24288 San Jose 50.42 USD 2.27 AUD
A22: 45544 | B22: 35 | C22: Z | E22: HUBBL - KAYO SPORTS NORTH RYDE
A23: 45546 | B23: 25.51 | C23: Z | E23: OF LONDON 16.49 USD 0.74 AUD
A24: 45546 | B24: 7.75 | C24: Z | E24: OF London 5.00 USD 0.23 AUD
A25: 45546 | B25: 7.75 | C25: Z | E25: OF London 5.00 USD 0.23 AUD
A26: 45547 | B26: 54.23 | C26: Z | E26: CMEDIA 6122345288 34.99 USD 1.58 AUD
A27: 45547 | B27: 32.2 | C27: Z | E27: ERGON 1 GLADESVILLE
A28: 45548 | B28: 20.69 | C28: Z | E28: RYDE MART PTY LTD NORTH RYDE
A29: 45551 | B29: 22.69 | C29: Z | E29: AFTERPAY AFTERPAY.COM/
... A34: 45565 | B34: 22.69 | C34: Z | E34: AFTERPAY HTTPSWWW.AFTE

Sheet NAB
A1: Date | B1: Amount | C1: GST CODE | D1: CATEGORY | E1: Transaction Type | F1: Transaction Details | G1: Category | H1: Merchant Name
A2: 45555 | B2: 96.43 | C2: B | D2: MOTOR MAINTENANCE | E2: CREDIT CARD PURCHASE | F2: XPERT CARWASH MACQUARIE PAR | G2: Uncategorised
B4: =SUM(B2:B3) -> 96.43 | C4: SUBTOTAL
B5: =B4/11 -> 8.7663636 | C5: GST
A7: 45537 | B7: 15 | C7: E | D7: BANK FEES | E7: MISCELLANEOUS CREDIT | F7: AUTO LATE FEE REVERSAL | G7: Refund
A8: 45537 | B8: 15 | C8: E | D8: BANK FEES | E8: MISCELLANEOUS DEBIT | F8: LATE PAYMENT FEE | G8: Fees
B11: =SUM(B7:B10) -> 30
A13: 45538 | B13: 904.99 | C13: P | D13: HEALTH INSURANCE | E13: CREDIT CARD PURCHASE | F13: WESTERN DISTRICT HEALT LITHGOW | G13: Insurance | H13: Westfund
A14: 45539 | B14: 1115.76 | C14: P | D14: INSURANCE | E14: CREDIT CARD PURCHASE | F14: ASTERON LIFE SYDNEY | G14: Insurance | H14: Asteron
A15: 45545 | B15: 638.89 | C15: P | D15: INSURANCE | E15: CREDIT CARD PURCHASE | F15: RESOLUTION LIFE QB SYDNEY | G15: Insurance | H15: Resolution Life Australasia
A16: 45551 | B16: 102 | C16: P | D16: MEDICAL-DOCTOR | E16: CREDIT CARD PURCHASE | F16: Hunters Hill Medical Werribee | G16: Medical | H16: Hunters Hill Medical Practice
A17: 45554 | B17: 200 | C17: P | D17: MEDICAL-SPEECH THERAPY | E17: CREDIT CARD PURCHASE | F17: CATE MADILL VOICE MELBOURNE | G17: Medical | H17: Cate Madill Voice & Speech
B19: =SUM(B13:B17) -> 2961.64 | C19: SUBTOTAL
A21: 45538 | B21: 178.31 | C21: Z | E21: CREDIT CARD PURCHASE | F21: PETCOVER SOVEREIGN TULLAMARINE | G21: Insurance | H21: Petcover
A22: 45554 | B22: 12.5 | C22: Z | E22: CREDIT CARD PURCHASE | F22: Zizanos North Ryde | G22: Caf√© & coffee | H22: Zizanos

Sheet PayPal
A1: Date | B1: Time | C1: Time zone | D1: Name | E1: Type | F1: Status | G1: Currency | H1: Gross | I1: Fee | J1: Net | K1: From email | L1: To email | M1: JPM Column - Effective Exchange Rate | N1: JPM Column Effective Cost | O1: Transaction ID | P1: Shipping address | Q1: Address status | R1: Item Title | S1: Item ID | T1: Shipping and handling amount | U1: Insurance Amount | V1: GST | W1: Option 1 Name | X1: Option 1 Value | Y1: Option 2 Name | Z1: Option 2 Value | AA1: Reference Txn ID | AB1: Invoice Number | AC1: Custom Number | AD1: Quantity | AE1: Receipt ID | AF1: Balance | AG1: Address line 1 | AH1: Address Line 2/District/Neighbourhood | AI1: Suburb | AJ1: State/Territory/Province/Region/County/Prefecture/Republic | AK1: Postcode | AL1: Country | AM1: Contact Phone Number | AN1: Subject | AO1: Note | AP1: Country Code | AQ1: Balance Impact

Sheet MAIN TXN ACC 000 0465 083 897
A1: Account Number | B1: Value Date | C1: Transaction Description | D1: Amount | E1: Amount Indicator | F1: OUR DISCRIPTION | G1: DESCRTIPION | H1: DEBITS | I1: DEBITS | J1: DEBITS | K1: DEBITS
A2: 465083897 | B2: 45538 | C2: INTERNET WITHDRAWAL 03SEP06:15 | CP Lease U301 | D2: 140 | E2: DR | F2: MOTOR EXPENSE | G2: B | H2: =IF(E2="DR",D2,0) -> 140 | I2: =IF(E2="CR",D2,0) -> 0 | J2: =IF(G2="E",0,H2/11) -> 12.727273 | K2: =IF(G2="E",0,I2/11) -> 0
A3: 465083897 | B3: 45545 | C3: ZIPMONEY | ZipMny P622232646 | D3: 54.32 | E3: DR | F3: INVOCIE | G3: B | H3: =IF(E3="DR",D3,0) -> 54.32 | I3: =IF(E3="CR",D3,0) -> 0 | J3: =IF(G3="E",0,H3/11) -> 4.9381818 | K3: =IF(G3="E",0,I3/11) -> 0
A4: 465083897 | B4: 45546 | C4: TFR WDL BPAY INTERNET 11SEP17:57 | 4303301000182145 nab cards | D4: 9000 | E4: DR | F4: JASON REPAYMENT | G4: E | H4: =IF(E4="DR",D4,0) -> 9000 | I4: =IF(E4="CR",D4,0) -> 0 | J4: =IF(G4="E",0,H4/11) -> 0 | K4: =IF(G4="E",0,I4/11) -> 0
A5: 465083897 | B5: 45546 | C5: TFR WDL BPAY INTERNET 11SEP17:57 | 5039468427563708 CreditLine | D5: 300 | E5: DR | F5: COMPUTER EQUIPMENT | G5: E | H5: =IF(E5="DR",D5,0) -> 300 | I5: =IF(E5="CR",D5,0) -> 0 | J5: =IF(G5="E",0,H5/11) -> 0 | K5: =IF(G5="E",0,I5/11) -> 0
A6: 465083897 | B6: 45547 | C6: INTERNET WITHDRAWAL 12SEP16:52 | 30001608667 | D6: 250 | E6: DR | F6: 1300 NUMBER | G6: B | H6: =IF(E6="DR",D6,0) -> 250 | I6: =IF(E6="CR",D6,0) -> 0 | J6: =IF(G6="E",0,H6/11) -> 22.727273 | K6: =IF(G6="E",0,I6/11) -> 0
A7: 465083897 | B7: 45547 | C7: Waverley Council | 239674 | D7: 1210 | E7: CR | F7: INVOCIE | G7: B | H7: =IF(E7="DR",D7,0) -> 0 | I7: =IF(E7="CR",D7,0) -> 1210 | J7: =IF(G7="E",0,H7/11) -> 0 | K7: =IF(G7="E",0,I7/11) -> 110
A8: 465083897 | B8: 45548 | C8: INTERNET WITHDRAWAL 13SEP02:48 | INV-7076 Masters Le Mesu | D8: 648.9 | E8: DR | F8: PROFESSIONAL FEES (ACCOUNTANT) | G8: B | H8: =IF(E8="DR",D8,0) -> 648.9 | I8: =IF(E8="CR",D8,0) -> 0 | J8: =IF(G8="E",0,H8/11) -> 58.990909 | K8: =IF(G8="E",0,I8/11) -> 0
A9: 465083897 | B9: 45548 | C9: INTERNET WITHDRAWAL 13SEP02:51 | INV-7076 Masters Le Mesu | D9: 1000 | E9: DR | F9: PROFESSIONAL FEES (ACCOUNTANT) | G9: B | H9: =IF(E9="DR",D9,0) -> 1000 | I9: =IF(E9="CR",D9,0) -> 0 | J9: =IF(G9="E",0,H9/11) -> 90.909091 | K9: =IF(G9="E",0,I9/11) -> 0
A10: 465083897 | B10: 45551 | C10: Ambulance Servic | 7849347 | D10: 2301.2 | E10: CR | F10: INVOICE | G10: B | H10: =IF(E10="DR",D10,0) -> 0 | I10: =IF(E10="CR",D10,0) -> 2301.2 | J10: =IF(G10="E",0,H10/11) -> 0 | K10: =IF(G10="E",0,I10/11) -> 209.2
A11: 465083897 | B11: 45552 | C11: INTERNET WITHDRAWAL 17SEP06:16 | CP Lease U301 | D11: 140 | E11: DR | F11: MOTOR EXPENSE | G11: B | H11: =IF(E11="DR",D11,0) -> 140 | I11: =IF(E11="CR",D11,0) -> 0 | J11: =IF(G11="E",0,H11/11) -> 12.727273 | K11: =IF(G11="E",0,I11/11) -> 0
A12: 465083897 | B12: 45554 | C12: INTERNET WITHDRAWAL 19SEP16:59 | SubCont IreneLomis | D12: 963.88 | E12: DR | F12: SUBCONT-LOMIS | G12: B | H12: =IF(E12="DR",D12,0) -> 963.88 | I12: =IF(E12="CR",D12,0) -> 0 | J12: =IF(G12="E",0,H12/11) -> 87.625455 | K12: =IF(G12="E",0,I12/11) -> 0
A13: 465083897 | B13: 45554 | C13: INTERNET WITHDRAWAL 19SEP16:59 | SubCont MichaelaB | D13: 3444.8 | E13: DR | F13: SUBCONT-BURKITT | G13: B | H13: =IF(E13="DR",D13,0) -> 3444.8 | I13: =IF(E13="CR",D13,0) -> 0 | J13: =IF(G13="E",0,H13/11) -> 313.16364 | K13: =IF(G13="E",0,I13/11) -> 0
... A16: 465083897 | B16: 45565 | C16: CREDIT INTEREST | D16: 35.68 | E16: CR | F16: BANK INTEREST | G16: E | H16: =IF(E16="DR",D16,0) -> 0 | I16: =IF(E16="CR",D16,0) -> 35.68 | J16: =IF(G16="E",0,H16/11) -> 0 | K16: =IF(G16="E",0,I16/11) -> 0
F18: TOTALS | H18: =SUM(H1:H17) -> 18316.9 | I18: =SUM(I1:I17) -> 3546.88 | J18: =SUM(J1:J17) -> 818.80909 | K18: =SUM(K1:K17) -> 319.2
F20: GST OWED | H20: =K18-J18 -> -499.60909

Sheet STG BANK ACCOUNT 431450521
A1: Account Number | B1: Value Date | C1: Transaction Description | D1: Account Currency | E1: Amount | F1: Amount Indicator | G1: Balance | H1: Balance Indicator | I1: DESCRTIPION | J1: GST EXMPT | K1: DEBITS | L1: CREDIT | M1: DEBIT GST | N1: CREDIT GST
A2: 431450521 | B2: 45352 | C2: INTERNET DEPOSIT 01MAR13:29 | Internal transfer | D2: 12000 | E2: CR | F2: INTERNAL TRANSACTION | G2: E | H2: =IF(E2="DR",D2,0) -> 0 | I2: =IF(E2="CR",D2,0) -> 12000 | J2: =IF(G2="E",0,H2/11) -> 0 | K2: =IF(G2="E",0,I2/11) -> 0
A3: 431450521 | B3: 45352 | C3: INTERNET WITHDRAWAL 01MAR13:42 | Reversal of Internal Ba | D3: 12000 | E3: DR | F3: INTERNAL TRANSACTION | G3: E | H3: =IF(E3="DR",D3,0) -> 12000 | I3: =IF(E3="CR",D3,0) -> 0 | J3: =IF(G3="E",0,H3/11) -> 0 | K3: =IF(G3="E",0,I3/11) -> 0

Sheet GST PROVISION 000 0455 884 826
A1: 455884826 | B1: 45007 | C1: INTERNET WITHDRAWAL 22MAR16:53 | Transfer from GST to Ma | D1: AUD | E1: 900 | F1: DR | G1: 10.85 | H1: CR | I1: INTERNAL TRANSFER | J1: E

Sheet ANZ - Advocating for Humanity

Sheet BUS FREEDOM ACCOUNT 431959205
A1: Account Number | B1: Value Date | C1: Transaction Description | D1: Cheque Serial Number | E1: Account Currency | F1: Amount | G1: Amount Indicator | H1: Balance | I1: Balance Indicator | J1: BSB | K1: Trancode

Sheet BUS SAV ACCOUNT 431450521
A1: Account Number | B1: Value Date | C1: Transaction Description | D1: Cheque Serial Number | E1: Amount | F1: Amount Indicator | G1: Balance | H1: Balance Indicator | I1: BSB | J1: Trancode

Sheet Personal ANZ 297380269

Sheet Tax Issues
D2: 17219.15
D5: -6392.75 | F5: Mortgage | I5: Business - loss - | K5: 154000
D6: -8000 | F6: tax
D8: =SUM(D2:D6) -> 2826.4 | I8: Moneies until 30 June - delay payment
I9: Member contribution into Super - reduces income
J10: Transition to Retirement schemen | N10: Talk to Geoff about impact
J15: 88000
J16: 36
J17: =J15/J16 -> 2444.4444
