Workbook

Sheet Transaction_Import
A1: Date | B1: Original_Description | C1: Amount | D1: Card_Account | E1: Auto_Category | F1: Auto_GST | G1: Auto_Type | H1: Manual_Category | I1: Manual_GST | J1: Final_Category | K1: Final_GST
A2: 45444 | B2: WORKSPACE365.COM.AU SYDNEY | D2: AMEX | E2: {=IFERROR(INDEX(Merchant_Lookup!$C$2:$C$27,MATCH(TRUE,ISNUMBER(SEARCH(Merchant_Lookup!$A$2:$A$26,UPPER(B2))),0)),"NEEDS REVIEW")} -> NEEDS REVIEW | F2: =IF(E2="NEEDS REVIEW","",INDEX(Merchant_Lookup!$D$2:$D$27,MATCH(E2,Merchant_Lookup!$C$2:$C$27,0))) | G2: =IF(E2="NEEDS REVIEW","",INDEX(Merchant_Lookup!$E$2:$E$27,MATCH(E2,Merchant_Lookup!$C$2:$C$27,0))) | I2: =IF(H2<>"",H2,E2) -> NEEDS REVIEW | J2: =IF(H2<>"",H2,E2) -> NEEDS REVIEW | K2: =IF(I2<>"",I2,F2) -> NEEDS REVIEW
E3: {=IFERROR(INDEX(Merchant_Lookup!$C$2:$C$27,MATCH(TRUE,ISNUMBER(SEARCH(Merchant_Lookup!$A$2:$A$26,UPPER(B3))),0)),"NEEDS REVIEW")} -> NEEDS REVIEW | F3: =IF(E3="NEEDS REVIEW","",INDEX(Merchant_Lookup!$D$2:$D$27,MATCH(E3,Merchant_Lookup!$C$2:$C$27,0))) | G3: =IF(E3="NEEDS REVIEW","",INDEX(Merchant_Lookup!$E$2:$E$27,MATCH(E3,Merchant_Lookup!$C$2:$C$27,0))) | I3: =IF(H3<>"",H3,E3) -> NEEDS REVIEW | J3: =IF(H3<>"",H3,E3) -> NEEDS REVIEW | K3: =IF(I3<>"",I3,F3) -> NEEDS REVIEW
E4: {=IFERROR(INDEX(Merchant_Lookup!$C$2:$C$27,MATCH(TRUE,ISNUMBER(SEARCH(Merchant_Lookup!$A$2:$A$26,UPPER(B4))),0)),"NEEDS REVIEW")} -> NEEDS REVIEW | F4: =IF(E4="NEEDS REVIEW","",INDEX(Merchant_Lookup!$D$2:$D$27,MATCH(E4,Merchant_Lookup!$C$2:$C$27,0))) | G4: =IF(E4="NEEDS REVIEW","",INDEX(Merchant_Lookup!$E$2:$E$27,MATCH(E4,Merchant_Lookup!$C$2:$C$27,0))) | I4: =IF(H4<>"",H4,E4) -> NEEDS REVIEW | J4: =IF(H4<>"",H4,E4) -> NEEDS REVIEW | K4: =IF(I4<>"",I4,F4) -> NEEDS REVIEW
E5: {=IFERROR(INDEX(Merchant_Lookup!$C$2:$C$27,MATCH(TRUE,ISNUMBER(SEARCH(Merchant_Lookup!$A$2:$A$26,UPPER(B5))),0)),"NEEDS REVIEW")} -> NEEDS REVIEW | F5: =IF(E5="NEEDS REVIEW","",INDEX(Merchant_Lookup!$D$2:$D$27,MATCH(E5,Merchant_Lookup!$C$2:$C$27,0))) | G5: =IF(E5="NEEDS REVIEW","",INDEX(Merchant_Lookup!$E$2:$E$27,MATCH(E5,Merchant_Lookup!$C$2:$C$27,0))) | I5: =IF(H5<>"",H5,E5) -> NEEDS REVIEW | J5: =IF(H5<>"",H5,E5) -> NEEDS REVIEW | K5: =IF(I5<>"",I5,F5) -> NEEDS REVIEW
E6: {=IFERROR(INDEX(Merchant_Lookup!$C$2:$C$27,MATCH(TRUE,ISNUMBER(SEARCH(Merchant_Lookup!$A$2:$A$26,UPPER(B6))),0)),"NEEDS REVIEW")} -> NEEDS REVIEW | F6: =IF(E6="NEEDS REVIEW","",INDEX(Merchant_Lookup!$D$2:$D$27,MATCH(E6,Merchant_Lookup!$C$2:$C$27,0))) | G6: =IF(E6="NEEDS REVIEW","",INDEX(Merchant_Lookup!$E$2:$E$27,MATCH(E6,Merchant_Lookup!$C$2:$C$27,0))) | I6: =IF(H6<>"",H6,E6) -> NEEDS REVIEW | J6: =IF(H6<>"",H6,E6) -> NEEDS REVIEW | K6: =IF(I6<>"",I6,F6) -> NEEDS REVIEW
E7: {=IFERROR(INDEX(Merchant_Lookup!$C$2:$C$27,MATCH(TRUE,ISNUMBER(SEARCH(Merchant_Lookup!$A$2:$A$26,UPPER(B7))),0)),"NEEDS REVIEW")} -> NEEDS REVIEW | F7: =IF(E7="NEEDS REVIEW","",INDEX(Merchant_Lookup!$D$2:$D$27,MATCH(E7,Merchant_Lookup!$C$2:$C$27,0))) | G7: =IF(E7="NEEDS REVIEW","",INDEX(Merchant_Lookup!$E$2:$E$27,MATCH(E7,Merchant_Lookup!$C$2:$C$27,0))) | I7: =IF(H7<>"",H7,E7) -> NEEDS REVIEW | J7: =IF(H7<>"",H7,E7) -> NEEDS REVIEW | K7: =IF(I7<>"",I7,F7) -> NEEDS REVIEW
E8: {=IFERROR(INDEX(Merchant_Lookup!$C$2:$C$27,MATCH(TRUE,ISNUMBER(SEARCH(Merchant_Lookup!$A$2:$A$26,UPPER(B8))),0)),"NEEDS REVIEW")} -> NEEDS REVIEW | F8: =IF(E8="NEEDS REVIEW","",INDEX(Merchant_Lookup!$D$2:$D$27,MATCH(E8,Merchant_Lookup!$C$2:$C$27,0))) | G8: =IF(E8="NEEDS REVIEW","",INDEX(Merchant_Lookup!$E$2:$E$27,MATCH(E8,Merchant_Lookup!$C$2:$C$27,0))) | I8: =IF(H8<>"",H8,E8) -> NEEDS REVIEW | J8: =IF(H8<>"",H8,E8) -> NEEDS REVIEW | K8: =IF(I8<>"",I8,F8) -> NEEDS REVIEW
E9: {=IFERROR(INDEX(Merchant_Lookup!$C$2:$C$27,MATCH(TRUE,ISNUMBER(SEARCH(Merchant_Lookup!$A$2:$A$26,UPPER(B9))),0)),"NEEDS REVIEW")} -> NEEDS REVIEW | F9: =IF(E9="NEEDS REVIEW","",INDEX(Merchant_Lookup!$D$2:$D$27,MATCH(E9,Merchant_Lookup!$C$2:$C$27,0))) | G9: =IF(E9="NEEDS REVIEW","",INDEX(Merchant_Lookup!$E$2:$E$27,MATCH(E9,Merchant_Lookup!$C$2:$C$27,0))) | I9: =IF(H9<>"",H9,E9) -> NEEDS REVIEW | J9: =IF(H9<>"",H9,E9) -> NEEDS REVIEW | K9: =IF(I9<>"",I9,F9) -> NEEDS REVIEW
E10: {=IFERROR(INDEX(Merchant_Lookup!$C$2:$C$27,MATCH(TRUE,ISNUMBER(SEARCH(Merchant_Lookup!$A$2:$A$26,UPPER(B10))),0)),"NEEDS REVIEW")} -> NEEDS REVIEW | F10: =IF(E10="NEEDS REVIEW","",INDEX(Merchant_Lookup!$D$2:$D$27,MATCH(E10,Merchant_Lookup!$C$2:$C$27,0))) | G10: =IF(E10="NEEDS REVIEW","",INDEX(Merchant_Lookup!$E$2:$E$27,MATCH(E10,Merchant_Lookup!$C$2:$C$27,0))) | I10: =IF(H10<>"",H10,E10) -> NEEDS REVIEW | J10: =IF(H10<>"",H10,E10) -> NEEDS REVIEW | K10: =IF(I10<>"",I10,F10) -> NEEDS REVIEW
E11: {=IFERROR(INDEX(Merchant_Lookup!$C$2:$C$27,MATCH(TRUE,ISNUMBER(SEARCH(Merchant_Lookup!$A$2:$A$26,UPPER(B11))),0)),"NEEDS REVIEW")} -> NEEDS REVIEW | F11: =IF(E11="NEEDS REVIEW","",INDEX(Merchant_Lookup!$D$2:$D$27,MATCH(E11,Merchant_Lookup!$C$2:$C$27,0))) | G11: =IF(E11="NEEDS REVIEW","",INDEX(Merchant_Lookup!$E$2:$E$27,MATCH(E11,Merchant_Lookup!$C$2:$C$27,0))) | I11: =IF(H11<>"",H11,E11) -> NEEDS REVIEW | J11: =IF(H11<>"",H11,E11) -> NEEDS REVIEW | K11: =IF(I11<>"",I11,F11) -> NEEDS REVIEW
E12: {=IFERROR(INDEX(Merchant_Lookup!$C$2:$C$27,MATCH(TRUE,ISNUMBER(SEARCH(Merchant_Lookup!$A$2:$A$26,UPPER(B12))),0)),"NEEDS REVIEW")} -> NEEDS REVIEW | F12: =IF(E12="NEEDS REVIEW","",INDEX(Merchant_Lookup!$D$2:$D$27,MATCH(E12,Merchant_Lookup!$C$2:$C$27,0))) | G12: =IF(E12="NEEDS REVIEW","",INDEX(Merchant_Lookup!$E$2:$E$27,MATCH(E12,Merchant_Lookup!$C$2:$C$27,0))) | I12: =IF(H12<>"",H12,E12) -> NEEDS REVIEW | J12: =IF(H12<>"",H12,E12) -> NEEDS REVIEW | K12: =IF(I12<>"",I12,F12) -> NEEDS REVIEW
E13: {=IFERROR(INDEX(Merchant_Lookup!$C$2:$C$27,MATCH(TRUE,ISNUMBER(SEARCH(Merchant_Lookup!$A$2:$A$26,UPPER(B13))),0)),"NEEDS REVIEW")} -> NEEDS REVIEW | F13: =IF(E13="NEEDS REVIEW","",INDEX(Merchant_Lookup!$D$2:$D$27,MATCH(E13,Merchant_Lookup!$C$2:$C$27,0))) | G13: =IF(E13="NEEDS REVIEW","",INDEX(Merchant_Lookup!$E$2:$E$27,MATCH(E13,Merchant_Lookup!$C$2:$C$27,0))) | I13: =IF(H13<>"",H13,E13) -> NEEDS REVIEW | J13: =IF(H13<>"",H13,E13) -> NEEDS REVIEW | K13: =IF(I13<>"",I13,F13) -> NEEDS REVIEW
E14: {=IFERROR(INDEX(Merchant_Lookup!$C$2:$C$27,MATCH(TRUE,ISNUMBER(SEARCH(Merchant_Lookup!$A$2:$A$26,UPPER(B14))),0)),"NEEDS REVIEW")} -> NEEDS REVIEW | F14: =IF(E14="NEEDS REVIEW","",INDEX(Merchant_Lookup!$D$2:$D$27,MATCH(E14,Merchant_Lookup!$C$2:$C$27,0))) | G14: =IF(E14="NEEDS REVIEW","",INDEX(Merchant_Lookup!$E$2:$E$27,MATCH(E14,Merchant_Lookup!$C$2:$C$27,0))) | I14: =IF(H14<>"",H14,E14) -> NEEDS REVIEW | J14: =IF(H14<>"",H14,E14) -> NEEDS REVIEW | K14: =IF(I14<>"",I14,F14) -> NEEDS REVIEW
... E223: {=IFERROR(INDEX(Merchant_Lookup!$C$2:$C$27,MATCH(TRUE,ISNUMBER(SEARCH(Merchant_Lookup!$A$2:$A$26,UPPER(B223))),0)),"NEEDS REVIEW")} -> NEEDS REVIEW | F223: =IF(E223="NEEDS REVIEW","",INDEX(Merchant_Lookup!$D$2:$D$27,MATCH(E223,Merchant_Lookup!$C$2:$C$27,0))) | G223: =IF(E223="NEEDS REVIEW","",INDEX(Merchant_Lookup!$E$2:$E$27,MATCH(E223,Merchant_Lookup!$C$2:$C$27,0))) | I223: =IF(H223<>"",H223,E223) -> NEEDS REVIEW | J223: =IF(H223<>"",H223,E223) -> NEEDS REVIEW | K223: =IF(I223<>"",I223,F223) -> NEEDS REVIEW

Sheet Merchant_Lookup
A1: Merchant_Pattern | B1: Merchant_Name | C1: Category | D1: GST_Code | E1: BUSINESS
A2: 2CO.COM*SUPERSOFT AMSTERDAM | B2: 2Co.com | C2: COMPUTER SUBSCRIPTIOIN | D2: E
A3: AAMI PI REALTIME BRISBANE | B3: AAMI | C3: INSURANCE
A4: AD FREE FOR PRIMEVIDEO SYDNEY | B4: Prime Ad Free | D4: Z
A5: ADOBE SYSTEMS Adobe Sys SAGGART | B5: ADOBE | C5: COMPUTER SUBSCRIPTIOIN | D5: B | E5: BUSINESS
A6: ADRENALINE HQ WEST RYDE | D6: Z
A7: AICD | B7: AICD | C7: PROFESSIONAL DEVELOPMENT | D7: B | E7: BUSINESS | F7: BUSINESS
A8: AMAYSIM MOBILE PTY LTD SYDNEY | B8: AMAYSIM | C8: MOBILE PHONE | D8: B | E8: BUSINESS
A9: AMAZON AU SYDNEY SOUTH | B9: Amazon | C9: AMAZON | F9: PERSONAL
A10: AMAZON MARKETPLACE AU SYDNEY SOUTH | B10: Amazon | C10: AMAZON
A11: AMAZON.CA PRIME MEMBER AMAZON.CA/PRI | B11: Amazon | C11: AMAZON
A12: AMPOL | B12: Ampol Fuel | C12: PETROL | D12: B | E12: BUSINESS
A13: AMZNPRIME | B13: Amazon Prime | C13: POSTAGE AND COURIERS | D13: B | E13: BUSINESS
A14: AP NORTH RYDE LPO NORTH RYDE | B14: Post Office | C14: POSTAGE AND COURIERS
A15: APPLE.COM | B15: Apple Services | C15: COMPUTER SUBSCRIPTION | D15: Z | E15: BUSINESS
A16: APPLE.COM/BILL SYDNEY | B16: Apple Services | C16: COMPUTER SUBSCRIPTION
A17: AUDIBLE PAYMENT AU SYDNEY | B17: AMAZON | D17: Z
A18: BEAUTIFUL.AI SAN FRANCISCO | B18: BEAUTIFUL AI | C18: COMPUTER SUBSCRIPTIOIN | D18: E | E18: BUSINESS
A19: BOX_UK LONDON | B19: BOX DMS | C19: COMPUTER SUBSCRIPTION | D19: E | E19: BUSINESS
A20: BP | B20: BP FUEL | C20: PETROL | D20: B | E20: BUSINESS
A21: CAFE | B21: CAFÉ | C21: TRAVEL-DOM-MEALS | D21: B | E21: BUSINESS
A22: CALM.COM SUBSCRIPTION PALO ALTO | B22: CALM | C22: COMPUTER SUBSCRIPTIOIN | D22: E | E22: BUSINESS
A23: CALTEX | B23: CALTEX | C23: PETROL | D23: B | E23: BUSINESS
A24: CENTR CREMORNE | D24: Z
A25: CHARLOTTES AT THE GRAN BROKEN HILL | B25: CHARLOTTES BH | C25: TRAVEL-DOM-MEALS | D25: B | E25: BUSINESS
A26: CHEMIST | B26: Chemist | C26: MEDICAL-PHARMA | D26: P | E26: PERSONAL
A27: CKO*FS *TECHSMITH 52422 FSPRG.NL | B27: TECHSMITH | C27: COMPUTER SOFTWARE | D27: E | E27: BUSINESS
A28: CKO*PATREON* MEMBERSHIP DUBLIN | D28: A
A29: CKO*RESOLUTTY.COM 52924 TALLINN | B29: RESOLUTTY | C29: COMPUTER SUBSCRIPTIOIN | D29: E | E29: BUSINESS
A30: COLES | B30: COLES | D30: Z
A31: D J*WSJ 800-568-7625 | B31: WSJ | C31: NEWSPAPERS & MAGAZINES | D31: E | E31: BUSINESS
A32: DBS*ANYTIME FITNESS N NORTH RYDE | B32: ANYTIME | D32: Z
A33: DELETEME SOMERVILLE | B33: DELETEME | C33: COMPUTER SUBSCRIPTIOIN | D33: E | E33: BUSINESS
A34: DESKY 0312 EAST BRISBANE | B34: DESKY | C34: OFFICE FURNITURE | D34: B | E34: BUSINESS
A35: DIGITAL RIVER GMBH COLOGNE | B35: DIGITAL RIVER | C35: COMPUTER SOFTWARE | D35: E | E35: BUSINESS
A36: DOCTOR | B36: DOCTOR | C36: MEDICAL-DOCTOR | D36: P | E36: PERSONAL
A37: DOUBLE | B37: DOUBLE TREE | C37: TRAVEL-DOM-ACCOMMODATION | D37: B | E37: BUSINESS
A38: EB* BRITANNICA 800-323-1229 | B38: BRITANICA | D38: Z
A39: EBAY O*04-11951-70948 SYDNEY | B39: EBAY | D39: Z
A40: EXETEL | B40: Exetel | C40: INTERNET | D40: B | E40: BUSINESS
...

Sheet Monthly_Summary

Sheet Instructions
A1: Date | B1: Original_Description | C1: Amount | D1: Card_Account | E1: Auto_Category | F1: Auto_GST | G1: Auto_Type | H1: Manual_Category | I1: Manual_GST | J1: Final_Category | K1: Final_GST
E2: {=IFERROR(INDEX(Merchant_Lookup!$C$2:$C$27,MATCH(TRUE,ISNUMBER(SEARCH(Merchant_Lookup!$A$2:$A$26,UPPER(B2))),0)),"NEEDS REVIEW")} -> NEEDS REVIEW | F2: =IF(E2="NEEDS REVIEW","",INDEX(Merchant_Lookup!$D$2:$D$27,MATCH(E2,Merchant_Lookup!$C$2:$C$27,0))) | G2: =IF(E2="NEEDS REVIEW","",INDEX(Merchant_Lookup!$E$2:$E$27,MATCH(E2,Merchant_Lookup!$C$2:$C$27,0))) | J2: =IF(H2<>"",H2,E2) -> NEEDS REVIEW | K2: =IF(I2<>"",I2,F2)
E3: {=IFERROR(INDEX(Merchant_Lookup!$C$2:$C$27,MATCH(TRUE,ISNUMBER(SEARCH(Merchant_Lookup!$A$2:$A$26,UPPER(B3))),0)),"NEEDS REVIEW")} -> NEEDS REVIEW | F3: =IF(E3="NEEDS REVIEW","",INDEX(Merchant_Lookup!$D$2:$D$27,MATCH(E3,Merchant_Lookup!$C$2:$C$27,0))) | G3: =IF(E3="NEEDS REVIEW","",INDEX(Merchant_Lookup!$E$2:$E$27,MATCH(E3,Merchant_Lookup!$C$2:$C$27,0))) | J3: =IF(H3<>"",H3,E3) -> NEEDS REVIEW | K3: =IF(I3<>"",I3,F3)
E4: {=IFERROR(INDEX(Merchant_Lookup!$C$2:$C$27,MATCH(TRUE,ISNUMBER(SEARCH(Merchant_Lookup!$A$2:$A$26,UPPER(B4))),0)),"NEEDS REVIEW")} -> NEEDS REVIEW | F4: =IF(E4="NEEDS REVIEW","",INDEX(Merchant_Lookup!$D$2:$D$27,MATCH(E4,Merchant_Lookup!$C$2:$C$27,0))) | G4: =IF(E4="NEEDS REVIEW","",INDEX(Merchant_Lookup!$E$2:$E$27,MATCH(E4,Merchant_Lookup!$C$2:$C$27,0))) | J4: =IF(H4<>"",H4,E4) -> NEEDS REVIEW | K4: =IF(I4<>"",I4,F4)
E5: {=IFERROR(INDEX(Merchant_Lookup!$C$2:$C$27,MATCH(TRUE,ISNUMBER(SEARCH(Merchant_Lookup!$A$2:$A$26,UPPER(B5))),0)),"NEEDS REVIEW")} -> NEEDS REVIEW | F5: =IF(E5="NEEDS REVIEW","",INDEX(Merchant_Lookup!$D$2:$D$27,MATCH(E5,Merchant_Lookup!$C$2:$C$27,0))) | G5: =IF(E5="NEEDS REVIEW","",INDEX(Merchant_Lookup!$E$2:$E$27,MATCH(E5,Merchant_Lookup!$C$2:$C$27,0))) | J5: =IF(H5<>"",H5,E5) -> NEEDS REVIEW | K5: =IF(I5<>"",I5,F5)
E6: {=IFERROR(INDEX(Merchant_Lookup!$C$2:$C$27,MATCH(TRUE,ISNUMBER(SEARCH(Merchant_Lookup!$A$2:$A$26,UPPER(B6))),0)),"NEEDS REVIEW")} -> NEEDS REVIEW | F6: =IF(E6="NEEDS REVIEW","",INDEX(Merchant_Lookup!$D$2:$D$27,MATCH(E6,Merchant_Lookup!$C$2:$C$27,0))) | G6: =IF(E6="NEEDS REVIEW","",INDEX(Merchant_Lookup!$E$2:$E$27,MATCH(E6,Merchant_Lookup!$C$2:$C$27,0))) | J6: =IF(H6<>"",H6,E6) -> NEEDS REVIEW | K6: =IF(I6<>"",I6,F6)
E7: {=IFERROR(INDEX(Merchant_Lookup!$C$2:$C$27,MATCH(TRUE,ISNUMBER(SEARCH(Merchant_Lookup!$A$2:$A$26,UPPER(B7))),0)),"NEEDS REVIEW")} -> NEEDS REVIEW | F7: =IF(E7="NEEDS REVIEW","",INDEX(Merchant_Lookup!$D$2:$D$27,MATCH(E7,Merchant_Lookup!$C$2:$C$27,0))) | G7: =IF(E7="NEEDS REVIEW","",INDEX(Merchant_Lookup!$E$2:$E$27,MATCH(E7,Merchant_Lookup!$C$2:$C$27,0))) | J7: =IF(H7<>"",H7,E7) -> NEEDS REVIEW | K7: =IF(I7<>"",I7,F7)
E8: {=IFERROR(INDEX(Merchant_Lookup!$C$2:$C$27,MATCH(TRUE,ISNUMBER(SEARCH(Merchant_Lookup!$A$2:$A$26,UPPER(B8))),0)),"NEEDS REVIEW")} -> NEEDS REVIEW | F8: =IF(E8="NEEDS REVIEW","",INDEX(Merchant_Lookup!$D$2:$D$27,MATCH(E8,Merchant_Lookup!$C$2:$C$27,0))) | G8: =IF(E8="NEEDS REVIEW","",INDEX(Merchant_Lookup!$E$2:$E$27,MATCH(E8,Merchant_Lookup!$C$2:$C$27,0))) | J8: =IF(H8<>"",H8,E8) -> NEEDS REVIEW | K8: =IF(I8<>"",I8,F8)
E9: {=IFERROR(INDEX(Merchant_Lookup!$C$2:$C$27,MATCH(TRUE,ISNUMBER(SEARCH(Merchant_Lookup!$A$2:$A$26,UPPER(B9))),0)),"NEEDS REVIEW")} -> NEEDS REVIEW | F9: =IF(E9="NEEDS REVIEW","",INDEX(Merchant_Lookup!$D$2:$D$27,MATCH(E9,Merchant_Lookup!$C$2:$C$27,0))) | G9: =IF(E9="NEEDS REVIEW","",INDEX(Merchant_Lookup!$E$2:$E$27,MATCH(E9,Merchant_Lookup!$C$2:$C$27,0))) | J9: =IF(H9<>"",H9,E9) -> NEEDS REVIEW | K9: =IF(I9<>"",I9,F9)
E10: {=IFERROR(INDEX(Merchant_Lookup!$C$2:$C$27,MATCH(TRUE,ISNUMBER(SEARCH(Merchant_Lookup!$A$2:$A$26,UPPER(B10))),0)),"NEEDS REVIEW")} -> NEEDS REVIEW | F10: =IF(E10="NEEDS REVIEW","",INDEX(Merchant_Lookup!$D$2:$D$27,MATCH(E10,Merchant_Lookup!$C$2:$C$27,0))) | G10: =IF(E10="NEEDS REVIEW","",INDEX(Merchant_Lookup!$E$2:$E$27,MATCH(E10,Merchant_Lookup!$C$2:$C$27,0))) | J10: =IF(H10<>"",H10,E10) -> NEEDS REVIEW | K10: =IF(I10<>"",I10,F10)
E11: {=IFERROR(INDEX(Merchant_Lookup!$C$2:$C$27,MATCH(TRUE,ISNUMBER(SEARCH(Merchant_Lookup!$A$2:$A$26,UPPER(B11))),0)),"NEEDS REVIEW")} -> NEEDS REVIEW | F11: =IF(E11="NEEDS REVIEW","",INDEX(Merchant_Lookup!$D$2:$D$27,MATCH(E11,Merchant_Lookup!$C$2:$C$27,0))) | G11: =IF(E11="NEEDS REVIEW","",INDEX(Merchant_Lookup!$E$2:$E$27,MATCH(E11,Merchant_Lookup!$C$2:$C$27,0))) | J11: =IF(H11<>"",H11,E11) -> NEEDS REVIEW | K11: =IF(I11<>"",I11,F11)
E12: {=IFERROR(INDEX(Merchant_Lookup!$C$2:$C$27,MATCH(TRUE,ISNUMBER(SEARCH(Merchant_Lookup!$A$2:$A$26,UPPER(B12))),0)),"NEEDS REVIEW")} -> NEEDS REVIEW | F12: =IF(E12="NEEDS REVIEW","",INDEX(Merchant_Lookup!$D$2:$D$27,MATCH(E12,Merchant_Lookup!$C$2:$C$27,0))) | G12: =IF(E12="NEEDS REVIEW","",INDEX(Merchant_Lookup!$E$2:$E$27,MATCH(E12,Merchant_Lookup!$C$2:$C$27,0))) | J12: =IF(H12<>"",H12,E12) -> NEEDS REVIEW | K12: =IF(I12<>"",I12,F12)
E13: {=IFERROR(INDEX(Merchant_Lookup!$C$2:$C$27,MATCH(TRUE,ISNUMBER(SEARCH(Merchant_Lookup!$A$2:$A$26,UPPER(B13))),0)),"NEEDS REVIEW")} -> NEEDS REVIEW | F13: =IF(E13="NEEDS REVIEW","",INDEX(Merchant_Lookup!$D$2:$D$27,MATCH(E13,Merchant_Lookup!$C$2:$C$27,0))) | G13: =IF(E13="NEEDS REVIEW","",INDEX(Merchant_Lookup!$E$2:$E$27,MATCH(E13,Merchant_Lookup!$C$2:$C$27,0))) | J13: =IF(H13<>"",H13,E13) -> NEEDS REVIEW | K13: =IF(I13<>"",I13,F13)
... E648: {=IFERROR(INDEX(Merchant_Lookup!$C$2:$C$27,MATCH(TRUE,ISNUMBER(SEARCH(Merchant_Lookup!$A$2:$A$26,UPPER(B648))),0)),"NEEDS REVIEW")} -> NEEDS REVIEW | F648: =IF(E648="NEEDS REVIEW","",INDEX(Merchant_Lookup!$D$2:$D$27,MATCH(E648,Merchant_Lookup!$C$2:$C$27,0))) | G648: =IF(E648="NEEDS REVIEW","",INDEX(Merchant_Lookup!$E$2:$E$27,MATCH(E648,Merchant_Lookup!$C$2:$C$27,0))) | J648: =IF(H648<>"",H648,E648) -> NEEDS REVIEW | K648: =IF(I648<>"",I648,F648)
